Workbook

Sheet 00_README
A1: Catalogo Servizi e Pricing — Angelini Academy
A4: Documento di lavoro per: | B4: Carlo Sanvoisin (HeyAI)
A5: Partner co-discussione economics: | B5: Daniele Caporale + Elena Chiti (FuturItaly)
A6: Cliente target: | B6: Angelini Academy (Angelini Industries — Communication & Brand)
A7: Data versione: | B7: Maggio 2026 — v1
A8: Status: | B8: Working draft per call Elena + raffinamento pricing
A10: INDICE FOGLI
A11: 00_README | B11: Guida d'uso + indice + legenda colori (questo foglio)
A12: 01_Master_Catalog | B12: Catalogo completo dei servizi con classificazione su 8 variabili strategiche
A13: 02_Pricing_Detail | B13: Calcoli pricing per ogni voce: effort, tariffa, costo, markup, prezzo cliente, margini
A14: 03_Pacchetti_Commerciali | B14: Struttura commerciale finale: P1 Sito · P2 Editoriale&Social · P3 FuturItaly · P4 Kit
A15: 04_Bundle_Sconti | B15: Logica sconti progressive su bundle, volume add-on, lock-in continuativi
A16: 05_Scenari_Vendita | B16: 3 scenari pre-calcolati: Entry · Standard · Premium + selector personalizzato
A17: 06_Call_Elena_FuturItaly | B17: Agenda call + voci P3 da quotare con FuturItaly + assumptions + gap
A18: 07_Variables | B18: Tariffe, sconti, parametri tutti modificabili — i numeri si aggiornano automaticamente
A20: LEGENDA COLORI
A21: Blu (testo) | B21: Input hardcoded — numeri che puoi cambiare per fare scenari
A22: Nero (testo) | B22: Formule e calcoli automatici — NON modificare manualmente
A23: Verde (testo) | B23: Link da altro foglio nello stesso workbook
A24: Sfondo giallo | B24: Assumption critica da rivedere/confermare
A25: Sfondo teal scuro | B25: Header tabella
A26: Sfondo grigio chiaro | B26: Sotto-header / sezione interna
A28: VARIABILI MASTER
A29: Tariffa HeyAI | B29: €750/giorno (vedi 07_Variables)
A30: Tariffa FuturItaly base + markup +15% | B30: €800/giorno × 1.15 = €920/giorno cliente
A31: Sconto bundle Fase 1+2 | B31: −5% sulla Fase 2
A32: Sconto bundle 1+2+3 completo | B32: −5% F2 + −10% F3
A33: Sconto volume add-on | B33: −5% (3 add-on) · −10% (4+) · −15% (tutti)
A34: Sconto lock-in continuativi | B34: −5% (12 mesi) · −10% (24 mesi)
A36: USO TIPICO
A37: 1. Riflessione pricing | B37: Apri 02_Pricing_Detail · cambia tariffe/effort in 07_Variables · controlla impatto
A38: 2. Conversazione con Michele (delivery) | B38: Verifica effort g/u in 02_Pricing_Detail · valida con realtà delivery
A39: 3. Call Elena (economics congiunti) | B39: Apri 06_Call_Elena_FuturItaly · usa come agenda + traccia decisioni
A40: 4. Sintesi commerciale verso cliente | B40: Apri 05_Scenari_Vendita · scegli scenario o costruisci custom
A41: 5. Negoziazione finale | B41: Modifica sconti in 04_Bundle_Sconti · gli scenari si ricalcolano
A43: REGOLE BLOCCANTI (skill investment-proposal-drafting HeyAI)
A44: Costo fornitore ≤ 60% del prezzo cliente | B44: Limite assoluto · target sano 40-45%
A45: Markup target ≥ 2.0x (sweet spot 50% margine) | B45: Mai aggregare voci che permettano ricostruzione monte ore
A46: Voci sempre aggregate al cliente | B46: Mai esposto dettaglio effort × tariffa nel documento consegna

Sheet 01_Master_Catalog
A1: Catalogo Master — Tutti i servizi classificati su 8 variabili
A2: Legenda V1-V8 in cima · ordinato per priorità · linka voci a 02_Pricing_Detail
A3: Codice | B3: Servizio | C3: Sottovoci / Cosa include | D3: V1 Owner | E3: V2 Natura | F3: V3 Brief | G3: V4 Priorità | H3: V5 Tipo | I3: V6 Fase | J3: Pacchetto
A4: P1.0 | B4: Riallineamento sito attuale (Fase 1) | C4: Refresh visivo · cambio copy minimo · cambio foto · 1-2 sezioni nuove · supporto pre-Festival Trento | D4: HeyAI | E4: Core | F4: Dentro brief | G4: Alta | H4: Progetto | I4: F1 Giu 2026 | J4: P1 SITO
A5: P1.1 | B5: Sito nuovo pubblico (Fase 2) | C5: 17 route · 5 percorsi (Talent · Researcher · HR&B · Imprese · Media) · MBA Gateway · Engaged Research preview · Founder Stories · Blog 3 stream · Eventi · Press · Chi Siamo · Contatti · Form base raccolta richieste · CMS · bilinguismo IT/EN · GDPR · hosting · QA · handover · PM 1g/sett | D5: HeyAI | E5: Core | F5: Extra-nostro | G5: Alta | H5: Progetto | I5: F2 Lug-Dic 2026 | J5: P1 SITO
A6: P1.A | B6: Studio strategico Customer Journey + analisi mercato | C6: Analisi 5 personas approfondita · journey mapping per persona · analisi mercato a supporto · documento strategico · prerequisito raccomandato P1.1 | D6: HeyAI | E6: Core | F6: Extra-nostro | G6: Alta | H6: Progetto | I6: Pre-F2 | J6: P1 SITO
A7: P1.B | B7: 4 MVP Intelligenza Artificiale verticali | C7: Tutor (contenuti Academy) · Reading Room (paper Engaged Research) · Career Path Navigator (percorso 5 personas) · Research Engine MVP (ricerca semantica) · LLM API + prompt eng + UI conversazionale + guardrail | D7: HeyAI | E7: Core | F7: Extra-nostro | G7: Alta | H7: Progetto | I7: F2 | J7: P1 SITO
A8: P1.C.1 | B8: Area Riservata Semplice | C8: Login dipendenti Gruppo · area unica senza differenziazione tenant · sezioni statiche · MVP minimo | D8: HeyAI | E8: Core | F8: Extra-nostro | G8: Media | H8: Progetto | I8: F2 | J8: P1 SITO
A9: P1.C.2 | B9: Area Riservata Avanzata (upgrade da C.1) | C9: Login singolo utente · Personal Learning Record (track record corsi · progressi · suggerimenti per dipendente) · sub-aree dedicate (5 aree) | D9: HeyAI | E9: Core | F9: Extra-nostro | G9: Media | H9: Progetto | I9: F2 | J9: P1 SITO
A10: P1.D | B10: Community Engaged Network | C10: 3 feature MVP: Paper Discussion Threads + Position Paper drafting collaborativo + Career Path Tracker · Hub editoriale community-only · riuso auth da C.1/C.2 · NO AI Co-pilot · NO Quiz pedagogico | D10: Congiunto | E10: Core | F10: Extra-nostro | G10: Alta | H10: Progetto | I10: F3 Q1 2027 | J10: P1 SITO
A11: P1.E | B11: Analytics native + Dashboard team interno | C11: Dashboard custom su dati nativi sito · metriche audience · conversione per persona · NO integrazioni esterne | D11: HeyAI | E11: Core | F11: Extra-nostro | G11: Media | H11: Progetto | I11: F2 | J11: P1 SITO
A12: P1.F | B12: Landing eventi pubblici | C12: Per evento: design landing dedicata · form registrazione · esperienza interattiva · lead capture · attivabile anche prima del sito nuovo | D12: HeyAI | E12: Core | F12: Extra-nostro | G12: Media | H12: On-demand | I12: OD | J12: P1 SITO
A13: P1.G | B13: Landing eventi interni | C13: Per evento: stessa logica di F ma con login richiesto · richiede P1.C.1 o P1.C.2 attivata | D13: HeyAI | E13: Core | F13: Extra-nostro | G13: Media | H13: On-demand | I13: OD | J13: P1 SITO
A14: P1.H | B14: SEO avanzata + topic authority | C14: 15 keyword priority mappate · long-tail dominance pedagogia/edTech · schema markup avanzato · content brief per autori · monitoring 3 mesi opzionale | D14: HeyAI | E14: Complementare | F14: Extra-nostro | G14: Media | H14: Progetto | I14: Add-on | J14: P1 SITO
... A31: P4.C | B31: Concept scouting gadget personalizzati | C31: Concept + scouting fornitori produzione esterna · opzionale | D31: HeyAI | E31: Satellite | F31: Dentro brief | G31: Bassa | H31: Progetto | I31: OD opzionale | J31: P4 KIT COMM

Sheet 02_Pricing_Detail
A1: Pricing Detail — Calcoli per ogni voce con formule live
A2: Effort g/u, tariffa, costo, prezzo cliente, margine. Modifica solo celle gialle/blu. Formule in nero.
A4: Codice | B4: Servizio | C4: Effort g/u HeyAI | D4: Effort g/u FuturItaly | E4: Costo HeyAI (calc) | F4: Costo FuturItaly cliente (calc) | G4: Prezzo cliente proposto | H4: Margine € (calc) | I4: Margine % (calc) | J4: Note pricing
A5: P1.0 | B5: Riallineamento sito attuale | C5: 8 | D5: 0 | E5: =C5*'07_Variables'!$B$5 | F5: — | G5: 6000 | H5: =G5-IFERROR(E5,0)-IFERROR(F5,0) | I5: =IFERROR(H5/G5,0) | J5: Minimo indispensabile · copy + foto + 1-2 sezioni · richiede accesso facile CMS attuale
A6: P1.1 | B6: Sito nuovo pubblico (Fase 2) | C6: 35 | D6: 0 | E6: =C6*'07_Variables'!$B$5 | F6: — | G6: 28000 | H6: =G6-IFERROR(E6,0)-IFERROR(F6,0) | I6: =IFERROR(H6/G6,0) | J6: Mid-range conservativo · sfrutta architettura esistente Claude Code + AI assistance
A7: P1.A | B7: Studio strategico CJ + analisi mercato | C7: 5 | D7: 0 | E7: =C7*'07_Variables'!$B$5 | F7: — | G7: 4000 | H7: =G7-IFERROR(E7,0)-IFERROR(F7,0) | I7: =IFERROR(H7/G7,0) | J7: Studio veloce con AI assistance · 5 personas approfondite + market analysis
A8: P1.B | B8: 4 MVP AI verticali | C8: 38 | D8: 0 | E8: =C8*'07_Variables'!$B$5 | F8: — | G8: 29000 | H8: =G8-IFERROR(E8,0)-IFERROR(F8,0) | I8: =IFERROR(H8/G8,0) | J8: Confermato Carlo · MVP LLM-based · prompt eng + UI conversazionale + guardrail
A9: P1.C.1 | B9: Area Riservata Semplice | C9: 12 | D9: 0 | E9: =C9*'07_Variables'!$B$5 | F9: — | G9: 8000 | H9: =G9-IFERROR(E9,0)-IFERROR(F9,0) | I9: =IFERROR(H9/G9,0) | J9: MVP minimo · login + area unica · no differenziazione tenant
A10: P1.C.2 | B10: Area Riservata Avanzata (upgrade) | C10: 20 | D10: 0 | E10: =C10*'07_Variables'!$B$5 | F10: — | G10: 15000 | H10: =G10-IFERROR(E10,0)-IFERROR(F10,0) | I10: =IFERROR(H10/G10,0) | J10: Aggiunge Personal Learning Record + sub-aree per singolo utente
A11: P1.D | B11: Community Engaged Network (3 feature MVP) | C11: 26 | D11: 0 | E11: =C11*'07_Variables'!$B$5 | F11: — | G11: 20000 | H11: =G11-IFERROR(E11,0)-IFERROR(F11,0) | I11: =IFERROR(H11/G11,0) | J11: 3 feature MVP · riuso auth da P1.C · NO AI moderator · NO Quiz
A12: P1.E | B12: Analytics + Dashboard interna | C12: 6 | D12: 0 | E12: =C12*'07_Variables'!$B$5 | F12: — | G12: 4500 | H12: =G12-IFERROR(E12,0)-IFERROR(F12,0) | I12: =IFERROR(H12/G12,0) | J12: Native su dati sito · no integrazioni esterne
A13: P1.F | B13: Landing eventi pubblici (media per landing) | C13: 10 | D13: 0 | E13: =C13*'07_Variables'!$B$5 | F13: — | G13: 7500 | H13: =G13-IFERROR(E13,0)-IFERROR(F13,0) | I13: =IFERROR(H13/G13,0) | J13: Range €5-10k per landing · valore mid usato qui
A14: P1.G | B14: Landing eventi interni (media per landing) | C14: 10 | D14: 0 | E14: =C14*'07_Variables'!$B$5 | F14: — | G14: 7500 | H14: =G14-IFERROR(E14,0)-IFERROR(F14,0) | I14: =IFERROR(H14/G14,0) | J14: Range €5-10k per landing · richiede P1.C attivata
A15: P1.H | B15: SEO avanzata (una tantum) | C15: 7 | D15: 0 | E15: =C15*'07_Variables'!$B$5 | F15: — | G15: 5000 | H15: =G15-IFERROR(E15,0)-IFERROR(F15,0) | I15: =IFERROR(H15/G15,0) | J15: 2-3 giorni di lavoro effective con tool moderni
A16: P1.I | B16: Accessibility WCAG/EAA (add-on) | C16: 5 | D16: 0 | E16: =C16*'07_Variables'!$B$5 | F16: — | G16: 3500 | H16: =G16-IFERROR(E16,0)-IFERROR(F16,0) | I16: =IFERROR(H16/G16,0) | J16: Audit + fix per conformità EAA UE
... A18: P1.K | B18: Integrazione tecnica email marketing | C18: 3 | D18: 0 | E18: =C18*'07_Variables'!$B$5 | F18: — | G18: 2500 | H18: =G18-IFERROR(E18,0)-IFERROR(F18,0) | I18: =IFERROR(H18/G18,0) | J18: Solo connessione form sito → piattaforma email
A19: P2.0W | B19: Workshop iniziale (mid-range) | C19: 15 | D19: 2 | E19: =C19*'07_Variables'!$B$5 | F19: =D19*'07_Variables'!$B$8 | G19: 10000 | H19: =G19-IFERROR(E19,0)-IFERROR(F19,0) | I19: =IFERROR(H19/G19,0) | J19: Range €8-12k · valore mid usato · workshop + copywriting + press kit + 2 Founder Stories
A20: P2.0C | B20: Continuativo mensile contenuti | C20: 4 | D20: 1 | E20: =C20*'07_Variables'!$B$5 | F20: =D20*'07_Variables'!$B$8 | G20: 3000 | H20: =G20-IFERROR(E20,0)-IFERROR(F20,0) | I20: =IFERROR(H20/G20,0) | J20: €3k/mese · ~5 g/mese mix HeyAI+FI · PM incluso
A21: P2.1 | B21: PM & Operations | C21: 0 | D21: 0 | E21: — | F21: — | G21: 0 | H21: — | I21: — | J21: INCLUSO DI DEFAULT in P2.0C · non quotato a parte · ore extra on-demand su richiesta
A22: P2.A | B22: Gestione LinkedIn Academy mensile | C22: 6 | D22: 0 | E22: =C22*'07_Variables'!$B$5 | F22: — | G22: 4500 | H22: =G22-IFERROR(E22,0)-IFERROR(F22,0) | I22: =IFERROR(H22/G22,0) | J22: €4.5k/mese · organic + paid management + visual social card · budget media a parte cliente
A23: P2.BS | B23: Email marketing setup | C23: 5 | D23: 0 | E23: =C23*'07_Variables'!$B$5 | F23: — | G23: 3500 | H23: =G23-IFERROR(E23,0)-IFERROR(F23,0) | I23: =IFERROR(H23/G23,0) | J23: Setup piattaforma + segmentazione + template + 1-2 automation
A24: P2.BC | B24: Email marketing continuativo mensile | C24: 2 | D24: 0 | E24: =C24*'07_Variables'!$B$5 | F24: — | G24: 1500 | H24: =G24-IFERROR(E24,0)-IFERROR(F24,0) | I24: =IFERROR(H24/G24,0) | J24: €1.5k/mese · campagne segmentate + drip + reporting
A25: P2.C1 | B25: Integrazione CRM (su richiesta) | C25: TBD | D25: TBD | E25: TBD | F25: TBD | G25: TBD | H25: — | I25: — | J25: Quotato a parte su richiesta · range tipico €10-15k una tantum
A26: P2.C2 | B26: Gateway pagamento (su richiesta) | C26: TBD | D26: TBD | E26: TBD | F26: TBD | G26: TBD | H26: — | I26: — | J26: Quotato a parte su richiesta · range tipico €8-12k una tantum
A27: P3.A | B27: Rete accademica prima ondata (9 atenei) | C27: 0 | D27: TBD | E27: — | F27: TBD | G27: TBD | H27: — | I27: — | J27: Quotazione fornita da FuturItaly direttamente · NON aggiungere prezzo HeyAI
A28: P3.B | B28: Rete accademica seconda ondata (4 atenei) | C28: 0 | D28: TBD | E28: — | F28: TBD | G28: TBD | H28: — | I28: — | J28: Quotazione FuturItaly diretta
A29: P3.C | B29: Bandi UE finanza agevolata (per bando) | C29: 0 | D29: TBD | E29: — | F29: TBD | G29: TBD | H29: — | I29: — | J29: Quotazione FuturItaly diretta · su richiesta per ciascun bando
A30: P4.A | B30: Concept video promo | C30: TBD | D30: 0 | E30: TBD | F30: — | G30: TBD | H30: — | I30: — | J30: Su quotazione su richiesta · cliente probabilmente ha fornitore dedicato
A31: P4.B | B31: Concept brochure | C31: TBD | D31: 0 | E31: TBD | F31: — | G31: TBD | H31: — | I31: — | J31: Su quotazione su richiesta
A32: P4.C | B32: Concept scouting gadget | C32: TBD | D32: 0 | E32: TBD | F32: — | G32: TBD | H32: — | I32: — | J32: Su quotazione su richiesta

Sheet 03_Pacchetti_Commerciali
A1: Pacchetti Commerciali — struttura di vendita finale
A2: 4 pacchetti: P1 SITO · P2 EDITORIALE&SOCIAL · P3 FUTURITALY · P4 KIT COMM. Modularità à la carte.
A4: P1 — SITO WEB
A5: Codice | B5: Voce | C5: Tipologia | D5: Prezzo proposto | E5: Note
A6: Nucleo (alternative)
A7: P1.0 | B7: Riallineamento sito attuale | C7: Progetto Fase 1 | D7: € 6.000 | E7: Entry minimo · pre-Festival Trento
A8: P1.1 | B8: Sito web pubblico nuovo (Fase 2) | C8: Progetto Fase 2 | D8: € 28.000 | E8: NUCLEO sito · 2-3 mesi delivery
A9: Add-on modulari
A10: P1.A | B10: Studio strategico CJ + analisi mercato | C10: Pre-F2 | D10: € 4.000 | E10: Prerequisito raccomandato se P1.1
A11: P1.B | B11: 4 MVP Intelligenza Artificiale | C11: F2 | D11: € 29.000 | E11: Confermato Carlo
A12: P1.C.1 | B12: Area Riservata Semplice | C12: F2 | D12: € 8.000 | E12: Login + area unica
A13: P1.C.2 | B13: Area Riservata Avanzata (upgrade) | C13: F2 | D13: € 15.000 | E13: PLR per singolo utente · richiede C.1
A14: P1.D | B14: Community Engaged Network | C14: F3 Q1 2027 | D14: € 20.000 | E14: 3 feature MVP · riuso auth
A15: P1.E | B15: Analytics + Dashboard interna | C15: F2 | D15: € 4.500 | E15: Native dati sito
A16: P1.F | B16: Landing eventi pubblici | C16: On-demand | D16: € 5.000-10.000 cad | E16: Range per landing
A17: P1.G | B17: Landing eventi interni | C17: On-demand | D17: € 5.000-10.000 cad | E17: Richiede P1.C
A18: P1.H | B18: SEO avanzata + topic authority | C18: Add-on | D18: € 5.000 | E18: Una tantum
A19: P1.I | B19: Accessibility WCAG/EAA | C19: Add-on | D19: € 3.500 | E19: Vincolante UE
A20: P1.J | B20: Analytics setup GA4+Plausible | C20: Add-on | D20: € 3.000
A21: P1.K | B21: Integrazione email marketing | C21: Add-on | D21: € 2.500 | E21: Tecnica · solo collegamento
A23: P2 — EDITORIALE, SOCIAL & OPERATIONS
A24: Codice | B24: Voce | C24: Tipologia | D24: Prezzo proposto | E24: Note
A25: Nucleo continuativo
A26: P2.0W | B26: Workshop iniziale creazione contenuti | C26: Progetto una tantum | D26: € 8.000-12.000 | E26: Range · mid €10k
A27: P2.0C | B27: Creazione contenuti continuativo | C27: Canone mensile | D27: € 3.000/mese | E27: Copywriting incluso · PM incluso
A28: P2.1 | B28: PM & Operations | C28: Default | D28: INCLUSO | E28: Compreso in P2.0C (~15h/mese)
A29: Add-on continuativi
A30: P2.A | B30: Gestione LinkedIn Academy (organic+paid) | C30: Canone mensile | D30: € 4.500/mese | E30: Budget media a parte cliente
A31: P2.BS | B31: Email marketing — Setup | C31: Una tantum | D31: € 3.500
A32: P2.BC | B32: Email marketing — Continuativo | C32: Canone mensile | D32: € 1.500/mese
A33: Su richiesta
A34: P2.C1 | B34: Integrazione CRM | C34: On-demand | D34: Su quotazione su richiesta | E34: Range tipico €10-15k
A35: P2.C2 | B35: Gateway pagamento corsi | C35: On-demand | D35: Su quotazione su richiesta | E35: Range tipico €8-12k
A37: P3 — RETE ACCADEMICA & FINANZA AGEVOLATA (FuturItaly)
A38: Codice | B38: Voce | C38: Tipologia | D38: Prezzo proposto | E38: Note
A39: P3.A | B39: Sviluppo contatti accademici — prima ondata | C39: On-demand | D39: TBD FuturItaly | E39: 9 atenei IT/EU/UK · da quotare con Daniele/Elena
A40: P3.B | B40: Sviluppo contatti accademici — seconda ondata | C40: On-demand | D40: TBD FuturItaly | E40: 4 atenei USA/CN · post 12 mesi
A41: P3.C | B41: Pre-screening + accompagnamento bandi UE | C41: On-demand | D41: TBD FuturItaly | E41: Per bando · 5 bandi mappati · fino 100% fondo perduto
A43: P4 — KIT COMUNICAZIONE ESTERNA (opzionale)
A44: Codice | B44: Voce | C44: Tipologia | D44: Prezzo proposto | E44: Note
...

Sheet 04_Bundle_Sconti
A1: Bundle & Sconti — logica commerciale
A2: Tutti gli sconti modificabili in 07_Variables. Esempi di applicazione sotto.
A4: BUNDLE SITO (P1.0 + P1.1)
A5: Configurazione | B5: Calcolo | C5: Prezzo finale | D5: Risparmio
A6: Solo P1.0 | B6: =6000 | C6: 6000 | D6: —
A7: Solo P1.1 | B7: =28000 | C7: 28000 | D7: —
A8: Bundle P1.0 + P1.1 firmati insieme | B8: =6000+28000*(1-'07_Variables'!$B$10) | C8: =6000+28000*(1-'07_Variables'!$B$10) | D8: Sconto −5% su F2
A9: Bundle ecosistema completo (P1.0 + P1.1 + tutti 8 add-on) | B9: Vedi formula | D9: Sconto −15% su add-on (riga seguente sotto)
A11: BUNDLE COMPLETO 1+2+3 (sito + community)
A12: Voce | B12: Prezzo base | C12: Sconto | D12: Prezzo finale
A13: Fase 1 Riallineamento (P1.0) | B13: 6000 | C13: 0 | D13: =B13*(1-C13)
A14: Fase 2 Sito nuovo (P1.1) − 5% bundle 1+2 | B14: 28000 | C14: ='07_Variables'!$B$10 | D14: =B14*(1-C14)
A15: Fase 3 Community (P1.D) − 10% bundle completo | B15: 20000 | C15: ='07_Variables'!$B$11 | D15: =B15*(1-C15)
A16: TOTALE Bundle Completo F1+F2+F3 | B16: =SUM(B13:B15) | D16: =SUM(D13:D15)
A17: Risparmio vs fasi sciolte | D17: =B16-D16
A19: SCONTI VOLUME ADD-ON P1
A20: N add-on | B20: Sconto applicato | C20: Esempio
A21: 1 | B21: 0 | C21: Add-on a prezzo pieno
A22: 2 | B22: 0 | C22: Add-on a prezzo pieno
A23: 3 | B23: ='07_Variables'!$B$14 | C23: −5% su tutti gli add-on scelti
A24: 4+ | B24: ='07_Variables'!$B$15 | C24: −10% su tutti gli add-on scelti
A25: Tutti 8 | B25: ='07_Variables'!$B$16 | C25: −15% bundle ecosistema completo
A27: SCONTI LOCK-IN CONTINUATIVI P2
A28: Durata impegno | B28: Sconto sul canone mensile | C28: Note
A29: 6 mesi (min raccomandato) | B29: 0 | C29: Nessuno sconto · ma vincolo minimo
A30: 12 mesi | B30: ='07_Variables'!$B$19 | C30: −5% su canone
A31: 24 mesi | B31: ='07_Variables'!$B$20 | C31: −10% su canone

Sheet 05_Scenari_Vendita
A1: Scenari di Vendita — 3 livelli + selector custom
A2: 3 scenari aggregati su 12 mesi. Per scenario custom: usa colonna 'Selezionato' nella tabella sotto.
A4: Voce | B4: Prezzo unitario | C4: Entry | D4: Standard | E4: Premium | F4: Custom (Sì=1)
A5: P1.0 — Riallineamento sito attuale | B5: 6000 | C5: 1 | D5: 1 | E5: 1 | F5: 1
A6: P1.1 — Sito nuovo pubblico (Fase 2) | B6: 28000 | C6: 0 | D6: 1 | E6: 1 | F6: 0
A7: P1.A — Studio strategico CJ | B7: 4000 | C7: 0 | D7: 1 | E7: 1 | F7: 0
A8: P1.B — 4 MVP Intelligenza Artificiale | B8: 29000 | C8: 0 | D8: 1 | E8: 1 | F8: 0
A9: P1.C.1 — Area Riservata Semplice | B9: 8000 | C9: 0 | D9: 0 | E9: 1 | F9: 0
A10: P1.C.2 — Area Riservata Avanzata (upgrade) | B10: 15000 | C10: 0 | D10: 0 | E10: 0 | F10: 0
A11: P1.D — Community Engaged Network | B11: 20000 | C11: 0 | D11: 0 | E11: 1 | F11: 0
A12: P1.E — Analytics + Dashboard | B12: 4500 | C12: 0 | D12: 0 | E12: 1 | F12: 0
A13: P1.F — Landing eventi pubblici (3 landing) | B13: 22500 | C13: 0 | D13: 0 | E13: 1 | F13: 0
A14: P1.G — Landing eventi interni (3 landing) | B14: 22500 | C14: 0 | D14: 0 | E14: 0 | F14: 0
A15: P1.H — SEO avanzata | B15: 5000 | C15: 0 | D15: 0 | E15: 1 | F15: 0
A16: P1.I — Accessibility WCAG/EAA | B16: 3500 | C16: 0 | D16: 0 | E16: 1 | F16: 0
... A23: P2.BC×12 — Email marketing 12 mesi | B23: 18000 | C23: 0 | D23: 0 | E23: 1 | F23: 0
A24: SUBTOTALE HeyAI | C24: =SUMPRODUCT($B$5:$B$23,C5:C23) | D24: =SUMPRODUCT($B$5:$B$23,D5:D23) | E24: =SUMPRODUCT($B$5:$B$23,E5:E23) | F24: =SUMPRODUCT($B$5:$B$23,F5:F23)
A25: Sconto bundle 1+2 (se entrambi) | C25: =IF(AND(C5=1,C6=1),-28000*'07_Variables'!$B$10,0) | D25: =IF(AND(D5=1,D6=1),-28000*'07_Variables'!$B$10,0) | E25: =IF(AND(E5=1,E6=1),-28000*'07_Variables'!$B$10,0) | F25: =IF(AND(F5=1,F6=1),-28000*'07_Variables'!$B$10,0)
A26: Sconto bundle 1+2+3 (se F3 incluso) | C26: =IF(AND(C5=1,C6=1,C11=1),-20000*'07_Variables'!$B$11,0) | D26: =IF(AND(D5=1,D6=1,D11=1),-20000*'07_Variables'!$B$11,0) | E26: =IF(AND(E5=1,E6=1,E11=1),-20000*'07_Variables'!$B$11,0) | F26: =IF(AND(F5=1,F6=1,F11=1),-20000*'07_Variables'!$B$11,0)
A27: 🎯 TOTALE Scenario (HeyAI puro, 12 mesi) | C27: =SUM(C24:C26) | D27: =SUM(D24:D26) | E27: =SUM(E24:E26) | F27: =SUM(F24:F26)
A28: + FuturItaly P3 (rete + bandi) | B28: TBD | C28: TBD | D28: TBD | E28: TBD | F28: TBD
A29: + Kit comunicazione esterna P4 (su richiesta) | C29: — | D29: — | E29: — | F29: —
A31: DESCRIZIONE SCENARI
A32: ENTRY | B32: P1.0 Riallineamento + P2.0C continuativo 12m + P2.A LinkedIn 12m. Cliente che vuole minimo intervento per restare allineato al brief. ~€96-100k anno 1.
A33: STANDARD | B33: Bundle 1+2 (sito riallineato + nuovo) + P1.A studio CJ + P1.B AI MVP + P2.0W workshop + continuativi 12m. Cliente che vuole il sito nuovo + ecosistema base.
A34: PREMIUM | B34: Tutto STANDARD + P1.C.1 area riservata + P1.D community + P1.E analytics + P1.F landing pubbliche + P1.H SEO + P1.I accessibility + P2.BS email setup + P2.BC continuativo. Cliente che sceglie ecosistema completo.
A35: CUSTOM | B35: Compila la colonna F con 1/0 per le voci che vuoi includere. Totale Custom si aggiorna automaticamente.

Sheet 06_Call_Elena_FuturItaly
A1: Call Elena FuturItaly — agenda + assumptions + gap
A3: Scopo della call: | B3: Allineare gli economics congiunti HeyAI + FuturItaly · raccogliere prezzi P3 · validare case history FuturItaly · confermare governance e fatturazione
A5: AGENDA CALL (30-45 min)
A6: 1. | B6: Briefing reciproco stato pitch Angelini (5 min) | C6: Allineamento veloce su tutto quello che abbiamo costruito
A7: 2. | B7: Conferma case history FuturItaly per S24 (5 min) | C7: Quale case usiamo · scope · metric · materiali grafici disponibili
A8: 3. | B8: Quotazione P3.A — Sviluppo contatti accademici prima ondata (10 min) | C8: 9 atenei IT/EU/UK · effort FuturItaly · prezzo cliente
A9: 4. | B9: Quotazione P3.B — Sviluppo contatti seconda ondata (5 min) | C9: 4 atenei USA/CN · effort + prezzo
A10: 5. | B10: Quotazione P3.C — Bandi UE accompagnamento (5 min) | C10: Per bando · accompagnamento + success fee?
A11: 6. | B11: Governance fatturazione (5 min) | C11: Fatturazione separata HeyAI ↔ FuturItaly verso cliente o unica?
A12: 7. | B12: Markup FuturItaly su servizi congiunti P2.0 (5 min) | C12: Conferma +15% markup su loro effort dentro P2.0 continuativo
A13: 8. | B13: Sintesi e prossimi step (3-5 min) | C13: Cosa serve da entrambi entro 28/5 per pitch 31/5-3/6
A15: VOCI P3 DA QUOTARE CON FUTURITALY
A16: Codice | B16: Voce | C16: Assumption iniziale HeyAI | D16: Da confermare con Elena
A17: P3.A | B17: Sviluppo rete prima ondata (9 atenei IT/EU/UK) | C17: Effort ~20-30 g FuturItaly su 6-12 mesi · prezzo cliente €12-18k stimato | D17: Effort reale · success fee per partnership attivata? · prezzo finale
A18: P3.B | B18: Sviluppo rete seconda ondata (4 atenei USA/CN) | C18: Effort ~10-15 g FuturItaly · prezzo cliente €8-12k stimato | D18: Stesso schema · attivazione differita 12 mesi
A19: P3.C | B19: Accompagnamento candidatura bando UE (per bando) | C19: Effort ~5-10 g FuturItaly per bando · prezzo cliente €4-8k per bando + eventuale success fee | D19: Per bando o pacchetto multi-bandi? · success fee % su sovvenzione ottenuta?
A20: Coordinamento Cattedra LUISS | B20: Continuativo · ricercatori partner | C20: Effort ~3-5 g FuturItaly/mese (Elena) · dentro P2.0C continuativo o separato? | D20: Decidere se è dentro P2.0C o canone separato FuturItaly
A22: DOMANDE APERTE PER ELENA
A23: Q1 | B23: Markup FuturItaly sopra costo base: confermi +15% su cliente?
A24: Q2 | B24: Tariffa giornaliera base FuturItaly: €800/giorno è realistico (assumption nostra) o diversa?
A25: Q3 | B25: Case history FuturItaly per S24 del pitch: quale proponi? Stato pre-screening + materiali disponibili?
A26: Q4 | B26: Bandi UE: success fee oltre fee di accompagnamento? Range tipico se sì?
A27: Q5 | B27: Coordinamento mensile Cattedra LUISS: dentro P2.0C o canone separato? Effort tuo realistico?
A28: Q6 | B28: Fatturazione: HeyAI fa fattura unica al cliente girando una quota a FuturItaly, o fatture separate FuturItaly diretto al cliente?
A29: Q7 | B29: Stato relazione con i 9 atenei prima ondata: già pre-contatti o partiamo da zero?
A30: Q8 | B30: Tempistiche realistiche P3.A: 6 mesi o 12 mesi per le 9 partnership? E quante realisticamente si attivano?
A31: Q9 | B31: Brand FuturItaly nel pitch: in che misura vuoi presenza visibile o restare partner sotto-traccia?
A32: Q10 | B32: Conflict / esclusiva: ci sono altri clienti FuturItaly nel corporate learning che potrebbero generare conflict?
A34: ASSUMPTIONS NOSTRE DA VALIDARE
A35: Assumption | B35: Valore stimato HeyAI | C35: Stato
A36: Tariffa giornaliera FuturItaly base | B36: € 800/giorno | C36: Da confermare
A37: Markup FuturItaly su cliente | B37: +15% | C37: Da confermare
A38: Tariffa cliente FuturItaly | B38: € 920/giorno | C38: Calcolata
A39: Effort Elena dentro P2.0C continuativo | B39: ~5-8 g/mese | C39: Da confermare con realtà delivery
A40: Effort Daniele dentro P2.0C continuativo | B40: ~2-3 g/mese | C40: Da confermare
A41: Tempistiche P3.A (9 atenei IT/EU/UK) | B41: 6-12 mesi | C41: Da confermare
A42: Tempistiche P3.B (4 atenei USA/CN) | B42: Post 12 mesi | C42: Da confermare
A43: Success rate atteso prima ondata | B43: 3-5 partnership su 9 contattati | C43: Da confermare
A45: DECISIONI DA PRENDERE INSIEME
A46: D1 | B46: Modello fatturazione HeyAI ↔ FuturItaly ↔ Cliente
...

Sheet 07_Variables
A1: Variabili e parametri master
A2: Tutti gli input sono in BLU. Modificare qui per impattare l'intero modello.
A4: Parametro | B4: Valore | C4: Unità | D4: Note
A5: TARIFFE GIORNALIERE
A6: Tariffa HeyAI €/giorno | B6: 750 | C6: € | D6: Mid-senior agency Italia 2026 con AI assistance
A7: Tariffa FuturItaly base €/giorno | B7: 800 | C7: € | D7: Stima · da confermare con Daniele/Elena
A8: Markup FuturItaly su cliente | B8: 0.15 | C8: % | D8: +15% sopra costo base FuturItaly
A9: Tariffa FuturItaly cliente €/giorno | B9: =B5*(1+B6) | C9: € | D9: Calcolata: base × (1 + markup)
A11: SCONTI BUNDLE SITO
A12: Sconto Fase 2 se bundle 1+2 | B12: 0.05 | C12: % | D12: Quando F1 e F2 firmate insieme
A13: Sconto Fase 3 se bundle 1+2+3 | B13: 0.1 | C13: % | D13: Quando tutte 3 fasi firmate insieme
A15: SCONTI VOLUME ADD-ON P1
A16: Soglia per attivare sconto add-on | B16: 3 | C16: n | D16: Numero minimo add-on per sconto
A17: Sconto se 3 add-on | B17: 0.05 | C17: %
A18: Sconto se 4+ add-on | B18: 0.1 | C18: %
A19: Sconto bundle ecosistema completo (tutti 8 add-on P1) | B19: 0.15 | C19: %
A21: SCONTI LOCK-IN CONTINUATIVI P2
A22: Sconto lock-in 12 mesi | B22: 0.05 | C22: % | D22: Sul canone mensile
A23: Sconto lock-in 24 mesi | B23: 0.1 | C23: % | D23: Sul canone mensile
A25: MARGINI TARGET
A26: Margine target sano (HeyAI) | B26: 0.55 | C26: % | D26: Sweet spot · % margine sul prezzo cliente
A27: Margine minimo accettabile | B27: 0.4 | C27: % | D27: Limite tattico
A28: Costo fornitore max ammesso | B28: 0.6 | C28: % | D28: Regola % BLOCCANTE skill HeyAI
A30: PARAMETRI DELIVERY
A31: Durata target sito nuovo (mesi) | B31: 2.5 | C31: mesi | D31: 2-3 mesi delivery Fase 2
A32: Giornata-uomo PM Carlo/settimana | B32: 1 | C32: g/sett | D32: Effort PM dedicato durante delivery
A33: Lock-in min raccomandato continuativi | B33: 6 | C33: mesi
A34: Validità offerta | B34: 30 | C34: giorni | D34: Da data emissione proposta
