Workbook

Sheet 00_README
A1: Catalogo Servizi e Pricing — Angelini Academy (v3)
A4: Documento di lavoro per: | B4: Carlo Sanvoisin (HeyAI)
A5: Partner economics: | B5: Daniele Caporale + Elena Chiti (FuturItaly)
A6: Cliente target: | B6: Angelini Academy (Angelini Industries — Communication & Brand)
A7: Data versione: | B7: Maggio 2026 — v3 (post-audit completo)
A8: Status: | B8: Working draft v3 · prezzi consolidati post audit dettagliato
A10: MODIFICHE v3 rispetto a v2
A11: P1.1 Sito nuovo Full | B11: €24.000 → €22.000 (margine 17-26%)
A12: P1.B 4 MVP AI | B12: €29.000 → €12.000 (MVP super-light · 1 agente adattivo + CPN)
A13: P1.C.1 Area Riservata Semplice | B13: €5.500 → €4.500 (benchmark login €500 + dashboard)
A14: P2.BS Email setup | B14: €1.500 → €1.800 (era sotto costo)
A15: P2.BC Email continuativo | B15: €1.300 → €1.500/mese (margine ragionevole)
A16: P2.0B Batch contenuti | B16: Confermato €7.000 con scope full Carlo (sotto costo consapevole)
A17: P2.0C Continuativo | B17: Confermato €2.100/mese (sotto costo consapevole · scope ricco)
A18: Tariffa HeyAI | B18: Confermata €650/giorno
A19: Effort g/u | B19: Ricalcolato bottom-up per ogni voce post audit
A20: MODIFICHE v2 rispetto a v1
A21: Master Catalog | B21: Solo 7 colonne (rimosse V3 Brief, V4 Priorità, V6 Fase)
A22: Pricing Detail | B22: Solo 8 colonne (rimossi Margine € e Margine %)
A23: Variables | B23: Rimosse tariffe FuturItaly, markup FuturItaly, margini target HeyAI
A24: Tariffa HeyAI | B24: €650/giorno (era €750)
A25: Nomenclatura | B25: Regia Editoriale & Content Creation · Batch iniziale contenuti (workshop incluso)
A26: Owner Community Engaged Network | B26: Solo HeyAI (non più Congiunto)
A27: Accessibility | B27: RIMOSSA come add-on
A28: P1.1 Sito nuovo | B28: €24.000 (target tuo · era €28.000)
A29: P1.C.1 / P1.C.2 / P1.D | B29: Prezzi abbassati con nuovo razionale benchmark
A30: Foglio Call Elena | B30: RIMOSSO dall'Excel · disponibile come specchietto in chat
A32: INDICE FOGLI
A33: 00_README | B33: Guida (questo foglio)
A34: 01_Master_Catalog | B34: Catalogo completo dei servizi su 7 variabili strategiche
A35: 02_Pricing_Detail | B35: Effort + costo + prezzo cliente per ogni voce (formule live)
A36: 03_Pacchetti_Commerciali | B36: Struttura commerciale: P1 SITO · P2 EDIT&SOCIAL · P3 FUTURITALY · P4 KIT
A37: 04_Bundle_Sconti | B37: Sconti bundle progressive, volume add-on, lock-in continuativi
A38: 05_Scenari_Vendita | B38: Entry · Standard · Premium + selector custom
A39: 06_Variables | B39: Parametri modificabili (tariffe, sconti)
A41: LEGENDA COLORI
A42: Blu (testo) + sfondo giallo | B42: Input modificabile — cambia qui per scenari
A43: Nero (testo) | B43: Formula automatica — NON modificare
A44: Verde (testo) | B44: Link cross-foglio
A45: Sfondo teal scuro | B45: Header tabella
...

Sheet 01_Master_Catalog
A1: Catalogo Master — Tutti i servizi classificati
A2: 7 variabili strategiche · filtri attivi · ordinato per pacchetto
A3: Codice | B3: Servizio | C3: Sottovoci / Cosa include | D3: V1 Owner | E3: V2 Natura | F3: V5 Tipo | G3: Pacchetto
A4: P1.0 | B4: Riallineamento sito attuale (Fase 1) | C4: Refresh visivo · cambio copy minimo · cambio foto · 1-2 sezioni nuove · supporto pre-Festival Trento | D4: HeyAI | E4: Core | F4: Progetto | G4: P1 SITO
A5: P1.1 | B5: Sito nuovo pubblico (Fase 2) | C5: 17 route · 5 percorsi (Talent · Researcher · HR&B · Imprese · Media) · MBA Gateway · Engaged Research preview · Founder Stories · Blog 3 stream · Eventi · Press · Chi Siamo · Contatti · Form base raccolta richieste · CMS · bilinguismo IT/EN · GDPR · hosting · QA · handover · PM 1g/sett | D5: HeyAI | E5: Core | F5: Progetto | G5: P1 SITO
A6: P1.A | B6: Studio strategico Customer Journey + analisi mercato | C6: Analisi 5 personas approfondita · journey mapping per persona · analisi mercato a supporto · documento strategico · prerequisito raccomandato P1.1 | D6: HeyAI | E6: Core | F6: Progetto | G6: P1 SITO
A7: P1.B | B7: 4 MVP Intelligenza Artificiale verticali | C7: Tutor (contenuti Academy) · Reading Room (paper Engaged Research) · Career Path Navigator (percorso 5 personas) · Research Engine MVP (ricerca semantica) · LLM API + prompt eng + UI conversazionale + guardrail | D7: HeyAI | E7: Core | F7: Progetto | G7: P1 SITO
A8: P1.C.1 | B8: Area Riservata Semplice | C8: Login dipendenti Gruppo · area unica senza differenziazione tenant · sezioni statiche · MVP minimo | D8: HeyAI | E8: Core | F8: Progetto | G8: P1 SITO
A9: P1.C.2 | B9: Area Riservata Avanzata (upgrade da C.1) | C9: Login singolo utente · Personal Learning Record (track record corsi · progressi · suggerimenti per dipendente) · sub-aree dedicate | D9: HeyAI | E9: Core | F9: Progetto | G9: P1 SITO
A10: P1.D | B10: Community Engaged Network | C10: 3 feature MVP: Paper Discussion Threads + Position Paper drafting collaborativo + Career Path Tracker · Hub editoriale community-only · riuso auth da C.1/C.2 · NO AI Co-pilot · NO Quiz pedagogico | D10: HeyAI | E10: Core | F10: Progetto | G10: P1 SITO
A11: P1.E | B11: Analytics native + Dashboard team interno | C11: Dashboard custom su dati nativi sito · metriche audience · conversione per persona · NO integrazioni esterne | D11: HeyAI | E11: Core | F11: Progetto | G11: P1 SITO
A12: P1.F | B12: Landing eventi pubblici | C12: Per evento: design landing dedicata · form registrazione · esperienza interattiva · lead capture · attivabile anche prima del sito nuovo | D12: HeyAI | E12: Core | F12: On-demand | G12: P1 SITO
A13: P1.G | B13: Landing eventi interni | C13: Per evento: stessa logica di F ma con login richiesto · richiede P1.C.1 o P1.C.2 attivata | D13: HeyAI | E13: Core | F13: On-demand | G13: P1 SITO
A14: P1.H | B14: SEO avanzata + topic authority | C14: 15 keyword priority mappate · long-tail dominance pedagogia/edTech · schema markup avanzato · content brief per autori · monitoring 3 mesi opzionale | D14: HeyAI | E14: Complementare | F14: Progetto | G14: P1 SITO
... A30: P4.C | B30: Concept scouting gadget personalizzati | C30: Concept + scouting fornitori produzione esterna · opzionale | D30: HeyAI | E30: Satellite | F30: On-demand | G30: P4 KIT COMM

Sheet 02_Pricing_Detail
A1: Pricing Detail — Calcoli per ogni voce
A2: Effort, costo, prezzo cliente. NO assunzioni FuturItaly · NO margini. Modifica solo celle gialle/blu.
A4: Codice | B4: Servizio | C4: Effort g/u HeyAI | D4: Effort g/u FuturItaly | E4: Costo HeyAI (calc) | F4: Costo FuturItaly (TBD) | G4: Prezzo cliente proposto | H4: Note pricing
A5: P1.0 | B5: Riallineamento sito attuale | C5: 9 | D5: 0 | E5: =C5*'06_Variables'!$B$6 -> 5850 | F5: — | G5: 6000 | H5: Minimo indispensabile · copy + foto + 1-2 sezioni
A6: P1.1 | B6: Sito nuovo pubblico (Fase 2) | C6: 27 | D6: 0 | E6: =C6*'06_Variables'!$B$6 -> 17550 | F6: — | G6: 22000 | H6: FULL con CMS
A7: P1.A | B7: Studio strategico CJ + analisi mercato | C7: 6 | D7: 0 | E7: =C7*'06_Variables'!$B$6 -> 3900 | F7: — | G7: 4000
A8: P1.B | B8: 4 MVP AI verticali | C8: 14 | D8: 0 | E8: =C8*'06_Variables'!$B$6 -> 9100 | F8: — | G8: 12000 | H8: MVP super-light: 1 agente adattivo con KB diverse + master prompt + CPN rule-based ·
A9: P1.C.1 | B9: Area Riservata Semplice | C9: 6 | D9: 0 | E9: =C9*'06_Variables'!$B$6 -> 3900 | F9: — | G9: 4500 | H9: MVP minimo
A10: P1.C.2 | B10: Area Riservata Avanzata (upgrade) | C10: 17 | D10: 0 | E10: =C10*'06_Variables'!$B$6 -> 11050 | F10: — | G10: 11000 | H10: PLR per singolo utente · sub-aree
A11: P1.D | B11: Community Engaged Network (3 feature MVP) | C11: 23 | D11: 0 | E11: =C11*'06_Variables'!$B$6 -> 14950 | F11: — | G11: 15000
A12: P1.E | B12: Analytics + Dashboard interna | C12: 7 | D12: 0 | E12: =C12*'06_Variables'!$B$6 -> 4550 | F12: — | G12: 4500 | H12: Native su dati sito · no integrazioni esterne
A13: P1.F | B13: Landing eventi pubblici (media per landing) | C13: 11 | D13: 0 | E13: =C13*'06_Variables'!$B$6 -> 7150 | F13: — | G13: 7500 | H13: Range €5-10k per landing · valore mid usato
A14: P1.G | B14: Landing eventi interni (media per landing) | C14: 11 | D14: 0 | E14: =C14*'06_Variables'!$B$6 -> 7150 | F14: — | G14: 7500 | H14: Range €5-10k per landing · richiede P1.C attivata
A15: P1.H | B15: SEO avanzata (una tantum) | C15: 8 | D15: 0 | E15: =C15*'06_Variables'!$B$6 -> 5200 | F15: — | G15: 5000 | H15: Una tantum · benchmark Italia
A16: P1.J | B16: Analytics setup base GA4+Plausible | C16: 5 | D16: 0 | E16: =C16*'06_Variables'!$B$6 -> 3250 | F16: — | G16: 3000 | H16: Setup tecnico + eventi conversion
A17: P1.K | B17: Integrazione tecnica email marketing | C17: 4 | D17: 0 | E17: =C17*'06_Variables'!$B$6 -> 2600 | F17: — | G17: 2500 | H17: Solo connessione form sito → piattaforma email
A18: P2.0B | B18: Batch iniziale contenuti (workshop incluso) | C18: 11 | D18: 0 | H18: workshop co-design con cliente + 8 articoli + 8 video pillole + sezioni sito associate + 5 founder stories + 5 alumni stories + press kit
A19: P2.0C | B19: Regia Editoriale & Content Creation continuativo mensile | C19: 3.5 | D19: 0 | H19: PM incluso · copywriting incluso (3 articoli + 3 video pillole + sezioni sito associate + 1 founder + 1 alumni
A20: P2.1 | B20: PM & Operations | C20: 0 | D20: 0 | E20: — | F20: — | G20: 0 | H20: INCLUSO DI DEFAULT in P2.0C · ore extra on-demand su richiesta
A21: P2.A | B21: Gestione LinkedIn Academy mensile | C21: 7 | D21: 0 | E21: =C21*'06_Variables'!$B$6 -> 4550 | F21: — | G21: 4500 | H21: €4.5k/mese · organic + paid · NO community management · budget media a parte
A22: P2.BS | B22: Email marketing setup | C22: 2.5 | D22: 0 | E22: =C22*'06_Variables'!$B$6 -> 1625 | F22: — | G22: 1800 | H22: Setup piattaforma + 5 segmentazioni + template + 1-2 automation
A23: P2.BC | B23: Email marketing continuativo mensile | C23: 2 | D23: 0 | E23: =C23*'06_Variables'!$B$6 -> 1300 | F23: — | G23: 1500 | H23: 1-2 campagne segmentate/mese · drip · A/B leggero · reporting
A24: P2.C1 | B24: Integrazione CRM (su richiesta) | C24: TBD | D24: 0 | E24: TBD | F24: — | G24: TBD | H24: Quotato a parte su richiesta
A25: P2.C2 | B25: Gateway pagamento (su richiesta) | C25: TBD | D25: 0 | E25: TBD | F25: — | G25: TBD | H25: Quotato a parte su richiesta
A26: P4.A | B26: Concept video promo | C26: TBD | D26: 0 | E26: TBD | F26: — | G26: TBD | H26: Su quotazione su richiesta
A27: P4.B | B27: Concept brochure | C27: TBD | D27: 0 | E27: TBD | F27: — | G27: TBD | H27: Su quotazione su richiesta
A28: P4.C | B28: Concept scouting gadget | C28: TBD | D28: 0 | E28: TBD | F28: — | G28: TBD | H28: Su quotazione su richiesta

Sheet 03_Pacchetti_Commerciali
A1: Pacchetti Commerciali — struttura di vendita finale
A2: 4 pacchetti: P1 SITO · P2 EDIT&SOCIAL · P3 FUTURITALY · P4 KIT
A4: P1 — SITO WEB
A5: Codice | B5: Voce | C5: Tipologia | D5: Prezzo proposto | E5: Note
A6: Nucleo (alternative)
A7: P1.0 | B7: Riallineamento sito attuale | C7: Progetto Fase 1 | D7: € 6.000 | E7: Entry minimo · pre-Festival Trento
A8: P1.1 | B8: Sito web pubblico nuovo (Fase 2) | C8: Progetto Fase 2 | D8: € 22.000 | E8: NUCLEO sito Full con CMS · 2-3 mesi delivery | H8: 22000
A9: Add-on modulari
A10: P1.A | B10: Studio strategico CJ + analisi mercato | C10: Pre-F2 | D10: € 4.000 | E10: Prerequisito raccomandato se P1.1 | H10: 4500
A11: P1.B | B11: 4 MVP Intelligenza Artificiale | C11: F2 | D11: € 12.000 | E11: MVP super-light · benchmark sviluppatore €8k/agente con riuso | H11: 15000
A12: P1.C.1 | B12: Area Riservata Semplice | C12: F2 | D12: € 4.500 | E12: Login + area unica · MVP minimo | H12: 4500
A13: P1.C.2 | B13: Area Riservata Avanzata (upgrade) | C13: F2 | D13: € 11.000 | E13: PLR per singolo utente · richiede C.1 | H13: 5000
A14: P1.D | B14: Community Engaged Network | C14: F3 Q1 2027 | D14: € 15.000 | E14: 3 feature MVP · riuso auth
A15: P1.E | B15: Analytics + Dashboard interna | C15: F2 | D15: € 4.500 | E15: Native dati sito | H15: =SUM(H8:H13) -> 51000
A16: P1.F | B16: Landing eventi pubblici | C16: On-demand | D16: € 5.000-10.000 cad | E16: Range per landing
A17: P1.G | B17: Landing eventi interni | C17: On-demand | D17: € 5.000-10.000 cad | E17: Richiede P1.C
A18: P1.H | B18: SEO avanzata + topic authority | C18: Add-on | D18: € 5.000 | E18: Una tantum
A19: P1.J | B19: Analytics setup GA4+Plausible | C19: Add-on | D19: € 3.000
A20: P1.K | B20: Integrazione email marketing | C20: Add-on | D20: € 2.500 | E20: Tecnica · solo collegamento
A22: P2 — EDITORIALE, SOCIAL & OPERATIONS
A23: Codice | B23: Voce | C23: Tipologia | D23: Prezzo proposto | E23: Note
A24: Nucleo
A25: P2.0B | B25: Batch iniziale contenuti (workshop incluso) | C25: Progetto una tantum | D25: 7000 | E25: Range · mid €10k
A26: P2.0C | B26: Regia Editoriale & Content Creation continuativo | C26: Canone mensile | D26: € 2.100/mese | E26: Copywriting incluso · PM incluso
A27: P2.1 | B27: PM & Operations | C27: Default | D27: INCLUSO | E27: Compreso in P2.0C (~15h/mese)
A28: Add-on continuativi
A29: P2.A | B29: Gestione LinkedIn Academy (organic+paid) | C29: Canone mensile | D29: € 4.500/mese | E29: Budget media a parte cliente
A30: P2.BS | B30: Email marketing — Setup | C30: Una tantum | D30: € 1.800
A31: P2.BC | B31: Email marketing — Continuativo | C31: Canone mensile | D31: € 1.500/mese
A32: Su richiesta
A33: P2.C1 | B33: Integrazione CRM | C33: On-demand | D33: Su quotazione
A34: P2.C2 | B34: Gateway pagamento corsi | C34: On-demand | D34: Su quotazione
A36: P3 — RETE ACCADEMICA & FINANZA AGEVOLATA (FuturItaly)
A37: Codice | B37: Voce | C37: Tipologia | D37: Prezzo proposto | E37: Note
A38: P3.A | B38: Sviluppo contatti accademici — prima ondata | C38: On-demand | D38: TBD FuturItaly | E38: 9 atenei IT/EU/UK
A39: P3.B | B39: Sviluppo contatti accademici — seconda ondata | C39: On-demand | D39: TBD FuturItaly | E39: 4 atenei USA/CN · post 12 mesi
A40: P3.C | B40: Pre-screening + accompagnamento bandi UE | C40: On-demand | D40: TBD FuturItaly | E40: Per bando · 5 bandi mappati · fino 100% fondo perduto
A42: P4 — KIT COMUNICAZIONE ESTERNA (opzionale)
A43: Codice | B43: Voce | C43: Tipologia | D43: Prezzo proposto | E43: Note
A44: P4.A | B44: Concept video promo Academy | C44: On-demand | D44: Su quotazione su richiesta | E44: Cliente forse ha fornitore
...

Sheet 04_Bundle_Sconti
A1: Bundle & Sconti — logica commerciale
A2: Tutti gli sconti modificabili in 06_Variables.
A4: BUNDLE COMPLETO 1+2+3 (sito + community)
A5: Voce | B5: Prezzo base | C5: Sconto | D5: Prezzo finale
A6: Fase 1 Riallineamento (P1.0) | B6: 6000 | C6: 0 | D6: =B6*(1-C6) -> 6000
A7: Fase 2 Sito nuovo (P1.1) − 5% bundle 1+2 | B7: 22000 | C7: ='06_Variables'!$B$9 -> 0.05 | D7: =B7*(1-C7) -> 20900
A8: Fase 3 Community (P1.D) − 10% bundle completo | B8: 15000 | C8: ='06_Variables'!$B$10 -> 0.1 | D8: =B8*(1-C8) -> 13500
A9: TOTALE Bundle Completo F1+F2+F3 | B9: =SUM(B6:B8) -> 43000 | D9: =SUM(D6:D8) -> 40400
A10: Risparmio vs fasi sciolte | D10: =B9-D9 -> 2600
A12: SCONTI VOLUME ADD-ON P1
A13: N add-on | B13: Sconto applicato | C13: Esempio
A14: 1 | B14: 0 | C14: Add-on a prezzo pieno
A15: 2 | B15: 0 | C15: Add-on a prezzo pieno
A16: 3 | B16: ='06_Variables'!$B$14 -> 0.05 | C16: −5% su tutti gli add-on scelti
A17: 4+ | B17: ='06_Variables'!$B$15 -> 0.1 | C17: −10% su tutti gli add-on scelti
A18: Tutti | B18: ='06_Variables'!$B$16 -> 0.15 | C18: −15% bundle ecosistema completo
A20: SCONTI LOCK-IN CONTINUATIVI P2
A21: Durata impegno | B21: Sconto sul canone mensile | C21: Note
A22: 6 mesi (min raccomandato) | B22: 0 | C22: Nessuno sconto · vincolo minimo
A23: 12 mesi | B23: ='06_Variables'!$B$19 -> 0.05 | C23: −5% su canone
A24: 24 mesi | B24: ='06_Variables'!$B$20 -> 0.1 | C24: −10% su canone

Sheet 05_Scenari_Vendita
A1: Scenari di Vendita — 3 livelli + selector custom
A2: Scenari su 12 mesi · per scenario custom usa colonna 'Custom' con 1/0
A4: Voce | B4: Prezzo unitario | C4: Entry | D4: Standard | E4: Premium | F4: Custom (1/0)
A5: P1.0 — Riallineamento sito attuale | B5: 6000 | C5: 1 | D5: 1 | E5: 1 | F5: 1
A6: P1.1 — Sito nuovo pubblico (Fase 2) | B6: 22000 | C6: 0 | D6: 1 | E6: 1 | F6: 0
A7: P1.A — Studio strategico CJ | B7: 4000 | C7: 0 | D7: 1 | E7: 1 | F7: 0
A8: P1.B — 4 MVP Intelligenza Artificiale | B8: 12000 | C8: 0 | D8: 1 | E8: 1 | F8: 0
A9: P1.C.1 — Area Riservata Semplice | B9: 4500 | C9: 0 | D9: 0 | E9: 1 | F9: 0
A10: P1.C.2 — Area Riservata Avanzata (upgrade) | B10: 11000 | C10: 0 | D10: 0 | E10: 0 | F10: 0
A11: P1.D — Community Engaged Network | B11: 15000 | C11: 0 | D11: 0 | E11: 1 | F11: 0
A12: P1.E — Analytics + Dashboard | B12: 4500 | C12: 0 | D12: 0 | E12: 1 | F12: 0
A13: P1.F — Landing eventi pubblici (3 landing) | B13: 22500 | C13: 0 | D13: 0 | E13: 1 | F13: 0
A14: P1.G — Landing eventi interni (3 landing) | B14: 22500 | C14: 0 | D14: 0 | E14: 0 | F14: 0
A15: P1.H — SEO avanzata | B15: 5000 | C15: 0 | D15: 0 | E15: 1 | F15: 0
A16: P1.J — Analytics setup GA4+Plausible | B16: 3000 | C16: 0 | D16: 0 | E16: 0 | F16: 0
... A22: P2.BC ×12 — Email marketing 12 mesi | B22: 18000 | C22: 0 | D22: 0 | E22: 1 | F22: 0
A23: SUBTOTALE HeyAI | C23: =SUMPRODUCT($B$5:$B$22,C5:C22) -> 6000 | D23: =SUMPRODUCT($B$5:$B$22,D5:D22) -> 144000 | E23: =SUMPRODUCT($B$5:$B$22,E5:E22) -> 215300 | F23: =SUMPRODUCT($B$5:$B$22,F5:F22) -> 96000
A24: Sconto bundle 1+2 (se P1.0 e P1.1 entrambi) | B24: 22000 | C24: =IF(AND(C5=1,C6=1),-B6*'06_Variables'!$B$9,0) -> 0 | D24: =IF(AND(D5=1,D6=1),-B6*'06_Variables'!$B$9,0) -> -1100 | E24: =IF(AND(E5=1,E6=1),-B6*'06_Variables'!$B$9,0) -> -1100 | F24: =IF(AND(F5=1,F6=1),-B6*'06_Variables'!$B$9,0) -> 0
A25: Sconto bundle 1+2+3 (se F3 incluso) | C25: =IF(AND(C5=1,C6=1,C11=1),-B11*'06_Variables'!$B$10,0) -> 0 | D25: =IF(AND(D5=1,D6=1,D11=1),-B11*'06_Variables'!$B$10,0) -> 0 | E25: =IF(AND(E5=1,E6=1,E11=1),-B11*'06_Variables'!$B$10,0) -> -1500 | F25: =IF(AND(F5=1,F6=1,F11=1),-B11*'06_Variables'!$B$10,0) -> 0
A26: 🎯 TOTALE Scenario (HeyAI puro, 12 mesi) | C26: =SUM(C23:C25) -> 6000 | D26: =SUM(D23:D25) -> 142900 | E26: =SUM(E23:E25) -> 212700 | F26: =SUM(F23:F25) -> 96000
A27: + FuturItaly P3 (rete + bandi) | B27: TBD | C27: TBD | D27: TBD | E27: TBD | F27: TBD
A28: + Kit comunicazione esterna P4 (su richiesta) | B28: — | C28: — | D28: — | E28: — | F28: —
A30: DESCRIZIONE SCENARI
A31: ENTRY | B31: P1.0 Riallineamento + P2.0C continuativo 12m + P2.A LinkedIn 12m. Cliente che vuole minimo intervento.
A32: STANDARD | B32: Bundle 1+2 (riallineamento + sito nuovo) + P1.A studio CJ + P1.B AI MVP + P2.0B batch + continuativi 12m. Cliente che vuole sito nuovo + ecosistema base.
A33: PREMIUM | B33: STANDARD + P1.C.1 area riservata + P1.D community + P1.E analytics + P1.F 3 landing pubbliche + P1.H SEO + P2.BS email setup + P2.BC continuativo. Ecosistema completo.
A34: CUSTOM | B34: Compila colonna 'Custom' con 1/0 per voci che vuoi includere. Totale si aggiorna automaticamente.

Sheet 06_Variables
A1: Variabili e parametri master
A2: Tutti gli input modificabili (gialli/blu). Cambia qui · tutto il modello si aggiorna.
A4: Parametro | B4: Valore | C4: Unità | D4: Note
A5: TARIFFE GIORNALIERE
A6: Tariffa HeyAI €/giorno | B6: 650 | C6: € | D6: Mid-senior agency Italia 2026 con AI assistance
A8: SCONTI BUNDLE SITO
A9: Sconto Fase 2 se bundle 1+2 | B9: 0.05 | C9: % | D9: Quando F1 e F2 firmate insieme
A10: Sconto Fase 3 se bundle 1+2+3 | B10: 0.1 | C10: % | D10: Quando tutte 3 fasi firmate insieme
A12: SCONTI VOLUME ADD-ON P1
A13: Soglia per attivare sconto add-on | B13: 3 | C13: n
A14: Sconto se 3 add-on | B14: 0.05 | C14: %
A15: Sconto se 4+ add-on | B15: 0.1 | C15: %
A16: Sconto bundle ecosistema completo (tutti add-on) | B16: 0.15 | C16: %
A18: SCONTI LOCK-IN CONTINUATIVI P2
A19: Sconto lock-in 12 mesi | B19: 0.05 | C19: % | D19: Sul canone mensile
A20: Sconto lock-in 24 mesi | B20: 0.1 | C20: % | D20: Sul canone mensile
A22: PARAMETRI DELIVERY
A23: Durata target sito nuovo (mesi) | B23: 2.5 | C23: mesi | D23: 2-3 mesi
A24: Giornata-uomo PM Carlo/settimana | B24: 1 | C24: g/sett | D24: PM dedicato durante delivery
A25: Lock-in min raccomandato continuativi | B25: 6 | C25: mesi
A26: Validità offerta | B26: 30 | C26: giorni | D26: Da data emissione
